<?xml version='1.0'?>

<robot name="my_robot" xmlns:xacro="http://www.ros.org/wiki/xacro">
<xacro:include filename="$(find my_robot)/urdf/my_robot.gazebo" />

  <material name="blue">
    <color rgba="0.203125 0.23828125 0.28515625 1.0"/>
  </material>
  <material name="grey">
    <color rgba="0.2 0.2 0.2 1.0"/>
  </material>
  <material name="orange">
    <color rgba="1.0 0.423529411765 0.0392156862745 1.0"/>
  </material>
  <material name="red">
    <color rgba="0.80078125 0.12890625 0.1328125 1.0"/>
  </material>
  <material name="white">
    <color rgba="0.95 0.95 0.95 0.95"/>
  </material>
  
  <gazebo reference="chassis">
    <material>Gazebo/Red</material>
  </gazebo>
  <gazebo reference="camera">
    <material>Gazebo/Orange</material>
  </gazebo>
  <gazebo reference="right_wheel">
    <material>Gazebo/Grey</material>
  </gazebo>
  <gazebo reference="left_wheel">
    <material>Gazebo/Grey</material>
  </gazebo>
  <gazebo reference="block_on_chassis">
    <material>Gazebo/Blue</material>
  </gazebo>
  <gazebo reference="disk_on_block">
    <material>Gazebo/Red</material>
  </gazebo>
  <gazebo reference="right_wheel">
    <material>Gazebo/Grey</material>
  </gazebo>
  <gazebo reference="left_wheel">
    <material>Gazebo/Grey</material>
  </gazebo>

  <link name="robot_footprint"></link>

  <joint name="robot_footprint_joint" type="fixed">
    <origin xyz="0 0 0" rpy="0 0 0" />
    <parent link="robot_footprint"/>
    <child link="chassis" />
  </joint>

  <joint type="continuous" name="left_wheel_hinge">
    <origin xyz="0 0.15 0" rpy="0 0 0"/>
    <child link="left_wheel"/>
    <parent link="chassis"/>
    <axis xyz="0 1 0" rpy="0 0 0"/>
    <limit effort="10000" velocity="1000"/>
    <dynamics damping="1.0" friction="1.0"/>
  </joint>
  
  <joint type="continuous" name="right_wheel_hinge">
    <origin xyz="0 -0.15 0" rpy="0 0 0"/>
    <child link="right_wheel"/>
    <parent link="chassis"/>
    <axis xyz="0 1 0" rpy="0 0 0"/>
    <limit effort="10000" velocity="1000"/>
    <dynamics damping="1.0" friction="1.0"/>
  </joint>

  <joint name="camera_joint" type="fixed">
    <origin xyz="0.15 0 0.075" rpy="0 0 0" />
    <parent link="chassis"/>
    <axis xyz="0 1 0" rpy="0 0 0"/>
    <child link="camera" />
  </joint>

  <joint name="hokuyo_joint" type="fixed">
    <origin xyz="0 0 0.09" rpy="0 0 0" />
    <parent link="block_on_chassis"/>
    <axis xyz="0 1 0" rpy="0 0 0"/>
    <child link="hokuyo" />
  </joint>

  <joint name="block_on_chasis_joint" type="fixed">
    <origin xyz="0.0 0 0.09" rpy="0 0 0" />
    <parent link="chassis"/>
    <axis xyz="0 1 0" rpy="0 0 0"/>
    <child link="block_on_chassis" />
  </joint>

  <joint name="disk_on_block_joint" type="fixed">
    <origin xyz="0 0 0.05" rpy="0 0 0"/>
    <child link="disk_on_block"/>
    <parent link="block_on_chassis"/>
    <axis xyz="0 1 0" rpy="0 0 0"/>
  </joint>

  <joint name="camera_optical_joint" type="fixed">
    <origin xyz="0 0 0" rpy="-1.5707 0 -1.5707"/>
    <parent link="camera"/>
    <child link="camera_optical"/>
  </joint>

  <link name="camera_optical">
  </link>


  <link name='chassis'>
    <pose>0 0 0.1 0 0 0</pose>

    <inertial>
      <mass value="15.0"/>
      <origin xyz="0.0 0 0" rpy=" 0 0 0"/>
      <inertia
          ixx="0.1" ixy="0" ixz="0"
          iyy="0.1" iyz="0"
          izz="0.1"
      />
    </inertial>

    <collision name='collision'>
      <origin xyz="0 0 0" rpy=" 0 0 0"/> 
      <geometry>
        <box size=".4 .23 .1"/>
      </geometry>
    </collision>

    <visual name='chassis_visual'>
      <origin xyz="0 0 0" rpy=" 0 0 0"/>
      <geometry>
        <box size=".4 .25 .1"/>
      </geometry>
    </visual>

    <collision name='back_caster_collision'>
      <origin xyz="-0.15 0 -0.05" rpy=" 0 0 0"/>
      <geometry>
        <sphere radius="0.0499"/>
      </geometry>
    </collision>

    <visual name='back_caster_visual'>
      <origin xyz="-0.15 0 -0.05" rpy=" 0 0 0"/>
      <geometry>
        <sphere radius="0.05"/>
      </geometry>
    </visual>

    <collision name='front_caster_collision'>
      <origin xyz="0.15 0 -0.05" rpy=" 0 0 0"/>
      <geometry>
        <sphere radius="0.0499"/>
      </geometry>
    </collision>

    <visual name='front_caster_visual'>
      <origin xyz="0.15 0 -0.05" rpy=" 0 0 0"/>
      <geometry>
        <sphere radius="0.05"/>
      </geometry>
    </visual>
  </link>

  <link name='left_wheel'>
  
  <inertial>
      <mass value="5.0"/>
      <origin xyz="0 0 0" rpy="0 1.5707 1.5707" />
      <inertia
          ixx="0.1" ixy="0" ixz="0"
          iyy="0.1" iyz="0"
          izz="0.1"
      />
    </inertial>

  <collision name='left_wheel_collision'>
      <origin xyz="0 0 0" rpy="0 1.5707 1.5707" />
      <geometry>
        <cylinder radius="0.1" length="0.05"/>
      </geometry>
    </collision>
	
  <visual name='left_wheel_visual'>
      <origin xyz="0 0 0" rpy="0 1.5707 1.5707" />
      <geometry>
        <cylinder radius="0.1" length="0.05"/>
      </geometry>
    </visual>
  </link> 

  <link name='right_wheel'>
  
  <inertial>
      <mass value="5.0"/>
      <origin xyz="0 0 0" rpy="0 1.5707 1.5707" />
      <inertia
          ixx="0.1" ixy="0" ixz="0"
          iyy="0.1" iyz="0"
          izz="0.1"
      />
    </inertial>

  <collision name='right_wheel_collision'>
      <origin xyz="0 0 0" rpy="0 1.5707 1.5707" />
      <geometry>
        <cylinder radius="0.1" length="0.05"/>
      </geometry>
    </collision>
	
  <visual name='right_wheel_visual'>
      <origin xyz="0 0 0" rpy="0 1.5707 1.5707" />
      <geometry>
        <cylinder radius="0.1" length="0.05"/>
      </geometry>
    </visual>
  </link>   

  <link name='camera'>
  
  <inertial>
      <mass value="0.1"/>
      <origin xyz="0 0 0" rpy="0 0 0" />
      <inertia
          ixx="0.000001" ixy="0" ixz="0"
          iyy="0.000001" iyz="0"
          izz="0.000001"
      />
    </inertial>

  <collision name='camera_collision'>
      <origin xyz="0 0 0" rpy="0 0 0" />
      <geometry>
        <box size=".05 .05 .05"/>
      </geometry>
    </collision>
	
  <visual name='camera_visual'>
      <origin xyz="0 0 0" rpy="0 0 0" />
      <geometry>
        <box size=".05 .05 .05"/>
      </geometry>
    </visual>
  </link>

  <link name='hokuyo'>
  
  <inertial>
      <mass value=".00001"/>
      <origin xyz="0 0 0" rpy="0 0 0" />
      <inertia
          ixx="0.000001" ixy="0" ixz="0"
          iyy="0.000001" iyz="0"
          izz="0.000001"
      />
    </inertial>

  <collision name='hokuyo_collision'>
      <origin xyz="0 0 0" rpy="0 0 0" />
      <geometry>
        <box size="0.1 0.1 0.1"/>
      </geometry>
    </collision>
	
  <visual name='hokuyo_visual'>
      <origin xyz="0 0 0" rpy="0 0 0" />
      <geometry>
        <mesh filename = "package://my_robot/meshes/hokuyo.dae"/>
      </geometry>
    </visual>
  </link> 

  <link name='block_on_chassis'>
    <pose>0 0 0.1 0 0 0</pose>

    <inertial>
      <mass value="2.0"/>
      <origin xyz="0.0 0 0" rpy=" 0 0 0"/>
      <inertia
          ixx="0.1" ixy="0" ixz="0"
          iyy="0.1" iyz="0"
          izz="0.1"
      />
    </inertial>

    <collision name='block_on_chassis_collision'>
      <origin xyz="0 0 0" rpy=" 0 0 0"/> 
      <geometry>
        <box size=".15 .15 .08"/>
      </geometry>
    </collision>

    <visual name='block_on_chassis_visual'>
      <origin xyz="0 0 0" rpy=" 0 0 0"/>
      <geometry>
        <box size=".15 .15 .08"/>
      </geometry>
    </visual>
  </link>

  <link name='disk_on_block'>
  
    <inertial>
      <mass value="3.0"/>
      <origin xyz="0 0 0" rpy="0 0 0" />
      <inertia
          ixx="0.1" ixy="0" ixz="0"
          iyy="0.1" iyz="0"
          izz="0.1"
      />
    </inertial>

    <collision name='disk_on_block_collision'>
      <origin xyz="0 0 0" rpy="0 0 0" />
      <geometry>
        <cylinder radius="0.15" length="0.02"/>
      </geometry>
    </collision>
	
    <visual name='disk_on_block_visual'>
      <origin xyz="0 0 0" rpy="0 0 0" />
      <geometry>
        <cylinder radius="0.175" length="0.02"/>
      </geometry>
    </visual>
  </link>   

</robot>

